<?xml version="1.0" ?>
<!-- =================================================================================== -->
<!-- |    This document was autogenerated by xacro from pepper_robot_CPU_no_arms.xacro | -->
<!-- |    EDITING THIS FILE BY HAND IS NOT RECOMMENDED                                 | -->
<!-- =================================================================================== -->
<!--******************************************************************
 ****** File automatically generated by generate_urdf.py script ******
 *********************************************************************-->
<robot name="JulietteY20MP">
  <joint name="HeadYaw" type="revolute">
    <parent link="torso"/>
    <child link="Neck"/>
    <origin rpy="0 0 0" xyz="-0.038 0 0.3089"/>
    <axis xyz="0 0 1.0"/>
    <limit effort="5.428" lower="-2.08567" upper="2.08567" velocity="7.33998"/>
  </joint>
  <link name="Neck">
    <inertial>
      <mass value="0.27391"/>
      <inertia ixx="0.000343501" ixy="0" ixz="-1.88563e-05" iyy="0.000493898" iyz="2.09863e-06" izz="0.000215252"/>
      <origin rpy="0 0 0" xyz="-0.00207 0 -0.02636"/>
    </inertial>
    <visual>
      <geometry>
        <mesh filename="package://pepper_meshes/meshes/1.0/HeadYaw.dae" scale="0.1 0.1 0.1"/>
      </geometry>
      <origin rpy="0 0 0" xyz="0 0 0"/>
    </visual>
    <collision>
      <geometry>
        <mesh filename="package://pepper_meshes/meshes/1.0/HeadYaw_0.10.stl" scale="0.1 0.1 0.1"/>
      </geometry>
      <origin rpy="0 0 0" xyz="0 0 0"/>
    </collision>
  </link>
  <joint name="HeadPitch" type="revolute">
    <parent link="Neck"/>
    <child link="Head"/>
    <origin rpy="0 0 0" xyz="0 0 0"/>
    <axis xyz="0 1.0 0"/>
    <limit effort="2.666" lower="-0.706858" upper="0.637045" velocity="9.22756"/>
  </joint>
  <link name="Head">
    <inertial>
      <mass value="1.51893"/>
      <inertia ixx="0.00597209" ixy="0" ixz="0.000125138" iyy="0.0059054" iyz="4.3428e-07" izz="0.00570374"/>
      <origin rpy="0 0 0" xyz="0.00312 0 0.11152"/>
    </inertial>
    <visual>
      <geometry>
        <mesh filename="package://pepper_meshes/meshes/1.0/HeadPitch.dae" scale="0.1 0.1 0.1"/>
      </geometry>
      <origin rpy="0 0 0" xyz="0 0 0"/>
    </visual>
    <collision>
      <geometry>
        <mesh filename="package://pepper_meshes/meshes/1.0/HeadPitch_0.10.stl" scale="0.1 0.1 0.1"/>
      </geometry>
      <origin rpy="0 0 0" xyz="0 0 0"/>
    </collision>
  </link>
  <joint name="HipRoll" type="revolute">
    <parent link="Hip"/>
    <child link="torso"/>
    <origin rpy="0 0 0" xyz="0 0 0.079"/>
    <axis xyz="-1.0 0 0"/>
    <limit effort="10.1884" lower="-0.514872" upper="0.514872" velocity="2.27032"/>
  </joint>
  <link name="Hip">
    <inertial>
      <mass value="1.02338"/>
      <inertia ixx="0.00502422" ixy="0" ixz="-2.54911e-05" iyy="0.00640971" iyz="0.000159449" izz="0.00441082"/>
      <origin rpy="0 0 0" xyz="0.00032 0 -0.06039"/>
    </inertial>
    <visual>
      <geometry>
        <mesh filename="package://pepper_description/meshes/HipRoll.dae" scale="0.1 0.1 0.1"/>
      </geometry>
      <origin rpy="0 0 0" xyz="0 0 0"/>
    </visual>
    <collision>
      <geometry>
        <mesh filename="package://pepper_description/meshes/HipRoll_0.10.stl" scale="0.1 0.1 0.1"/>
      </geometry>
      <origin rpy="0 0 0" xyz="0 0 0"/>
    </collision>
  </link>
  <joint name="HipPitch" type="revolute">
    <parent link="Pelvis"/>
    <child link="Hip"/>
    <origin rpy="0 0 0" xyz="0 0 0.268"/>
    <axis xyz="0 -1.0 0"/>
    <limit effort="19.787" lower="-1.03847" upper="1.03847" velocity="2.93276"/>
  </joint>
  <link name="Pelvis">
    <inertial>
      <mass value="2.45917"/>
      <inertia ixx="0.034351" ixy="0" ixz="0.000223034" iyy="0.0303122" iyz="-8.37542e-05" izz="0.0143771"/>
      <origin rpy="0 0 0" xyz="0.00237 0 -0.09654"/>
    </inertial>
    <visual>
      <geometry>
        <mesh filename="package://pepper_description/meshes/HipPitch.dae" scale="0.1 0.1 0.1"/>
      </geometry>
      <origin rpy="0 0 0" xyz="0 0 0"/>
    </visual>
    <collision>
      <geometry>
        <mesh filename="package://pepper_description/meshes/HipPitch_0.10.stl" scale="0.1 0.1 0.1"/>
      </geometry>
      <origin rpy="0 0 0" xyz="0 0 0"/>
    </collision>
  </link>
  <joint name="KneePitch" type="revolute">
    <parent link="Tibia"/>
    <child link="Pelvis"/>
    <origin rpy="0 0 0" xyz="0 0 0"/>
    <axis xyz="0 -1.0 0"/>
    <limit effort="27.702" lower="-0.514872" upper="0.514872" velocity="2.93276"/>
  </joint>
  <link name="Tibia">
    <inertial>
      <!-- We increase the weight of the base and nullify anything but the diagonal on the inertia matrix
			to help the plugins that move the base to not slip in weird ways -->
      <mass value="1160.1499999999999"/>
      <inertia ixx="12.9229" ixy="-0.0" ixz="0.0" iyy="12.283900000000001" iyz="-0.0" izz="10.8168"/>
      <origin rpy="0 0 0" xyz="0.00220451 0 -0.185729"/>
    </inertial>
    <visual>
      <geometry>
        <mesh filename="package://pepper_meshes/meshes/1.0/KneePitch.dae" scale="0.1 0.1 0.1"/>
      </geometry>
      <origin rpy="0 0 0" xyz="0 0 0"/>
    </visual>
    <collision>
      <geometry>
        <!-- 				<mesh filename="package://pepper_meshes/meshes/1.0/KneePitch_0.10.stl" scale="0.1 0.1 0.1"/>
 -->
        <!-- We approximate the base with a box to ease the contacts with the ground so
                plugins that move the base actually work -->
        <box size="0.35 0.35 0.2"/>
      </geometry>
      <origin rpy="0 0 0" xyz="0 0 -0.24"/>
    </collision>
  </link>
  <joint name="base_footprint_joint" type="fixed">
    <parent link="base_footprint"/>
    <child link="Tibia"/>
    <origin rpy="0 0 0" xyz="0 0 0.334"/>
  </joint>
  <link name="base_footprint"/>
  <link name="base_link"/>
  <joint name="base_link_fixedjoint" type="fixed">
    <parent link="torso"/>
    <child link="base_link"/>
    <origin rpy="0 0 0" xyz="0 0 0"/>
    <axis xyz="0 0 0"/>
  </joint>
  <link name="torso">
    <inertial>
      <mass value="3.99533"/>
      <inertia ixx="0.0452761" ixy="0" ixz="0.00499091" iyy="0.0432702" iyz="-0.000266886" izz="0.0258881"/>
      <origin rpy="0 0 0" xyz="0.00322 0 -0.01029"/>
    </inertial>
    <visual>
      <geometry>
        <mesh filename="package://pepper_description/meshes/Torso.dae" scale="0.1 0.1 0.1"/>
      </geometry>
      <origin rpy="0 0 0" xyz="0 0 0"/>
    </visual>
    <collision>
      <geometry>
        <mesh filename="package://pepper_description/meshes/Torso_0.10.stl" scale="0.1 0.1 0.1"/>
      </geometry>
      <origin rpy="0 0 0" xyz="0 0 0"/>
    </collision>
  </link>
  <link name="SonarBack_frame"/>
  <joint name="Sonar/Back_sensor_fixedjoint" type="fixed">
    <parent link="Tibia"/>
    <child link="SonarBack_frame"/>
    <origin rpy="-1.81761e-08 -0.209438 -3.14159" xyz="-0.0718 0 -0.0534"/>
    <axis xyz="0 0 0"/>
  </joint>
  <link name="CameraBottom_optical_frame"/>
  <joint name="CameraBottom_optical_frame_fixedjoint" type="fixed">
    <parent link="CameraBottom_frame"/>
    <child link="CameraBottom_optical_frame"/>
    <origin rpy="-1.57079632679 0 -1.57079632679" xyz="0 0 0"/>
  </joint>
  <link name="CameraDepth_optical_frame"/>
  <joint name="CameraDepth_optical_frame_fixedjoint" type="fixed">
    <parent link="CameraDepth_frame"/>
    <child link="CameraDepth_optical_frame"/>
    <origin rpy="-1.57079632679 0 -1.57079632679" xyz="0 0 0"/>
  </joint>
  <!-- 	<link name="LHandTouchBack_frame"/>
	<joint name="LHand/Touch/Back_sensor_fixedjoint" type="fixed">
		<parent link="l_wrist"/>
		<child link="LHandTouchBack_frame"/>
		<origin rpy="1.5708 -1.5708 -3.14159" xyz="0.0523 0 0.0304"/>
		<axis xyz="0 0 0"/>
	</joint> -->
  <link name="VerticalLeftLaser_frame"/>
  <joint name="LaserSensor/VerticalLeft_sensor_fixedjoint" type="fixed">
    <parent link="Tibia"/>
    <child link="VerticalLeftLaser_frame"/>
    <origin rpy="0 0.349066 0" xyz="0.0562 0 -0.0692"/>
    <axis xyz="0 0 0"/>
  </joint>
  <link name="SurroundingFrontLaser_device_frame"/>
  <joint name="LaserSensor/Front_sensor_fixedjoint" type="fixed">
    <parent link="Tibia"/>
    <child link="SurroundingFrontLaser_device_frame"/>
    <origin rpy="0 0.349066 0" xyz="0.0562 0 -0.0692"/>
    <axis xyz="0 0 0"/>
  </joint>
  <link name="BumperB_frame"/>
  <joint name="Bumper/Back_sensor_fixedjoint" type="fixed">
    <parent link="Tibia"/>
    <child link="BumperB_frame"/>
    <origin rpy="0 0 -3.14159" xyz="-0.251 0 -0.264"/>
    <axis xyz="0 0 0"/>
  </joint>
  <link name="SurroundingLeftLaser_frame"/>
  <joint name="LaserSensor/Left_projected_sensor_fixedjoint" type="fixed">
    <parent link="Tibia"/>
    <child link="SurroundingLeftLaser_frame"/>
    <origin rpy="0 0 1.5707963267948966" xyz="-0.08600 0.10100 -0.30000"/>
    <axis xyz="0 0 0"/>
  </joint>
  <link name="ShovelLaser_frame"/>
  <joint name="LaserSensor/Shovel_sensor_fixedjoint" type="fixed">
    <parent link="Tibia"/>
    <child link="ShovelLaser_frame"/>
    <origin rpy="0 0.349066 0" xyz="0.0562 0 -0.0692"/>
    <axis xyz="0 0 0"/>
  </joint>
  <link name="ImuTorsoAccelerometer_frame"/>
  <joint name="Accelerometer_sensor_fixedjoint" type="fixed">
    <parent link="torso"/>
    <child link="ImuTorsoAccelerometer_frame"/>
    <origin rpy="0 0 0" xyz="0.00239 -0.03575 0.00626"/>
    <axis xyz="0 0 0"/>
  </joint>
  <link name="RSpeaker_frame"/>
  <joint name="SpeakerRight_sensor_fixedjoint" type="fixed">
    <parent link="Head"/>
    <child link="RSpeaker_frame"/>
    <origin rpy="0 0 0" xyz="0 0 0"/>
    <axis xyz="0 0 0"/>
  </joint>
  <link name="SurroundingRightLaser_device_frame"/>
  <joint name="LaserSensor/Right_sensor_fixedjoint" type="fixed">
    <parent link="Tibia"/>
    <child link="SurroundingRightLaser_device_frame"/>
    <origin rpy="0 0.349066 -1.5708" xyz="-0.018 -0.0899 -0.0759"/>
    <axis xyz="0 0 0"/>
  </joint>
  <link name="LSpeaker_frame"/>
  <joint name="SpeakerLeft_sensor_fixedjoint" type="fixed">
    <parent link="Head"/>
    <child link="LSpeaker_frame"/>
    <origin rpy="0 0 0" xyz="0 0 0"/>
    <axis xyz="0 0 0"/>
  </joint>
  <!-- 	<link name="RHandTouchBack_frame"/>
	<joint name="RHand/Touch/Back_sensor_fixedjoint" type="fixed">
		<parent link="r_wrist"/>
		<child link="RHandTouchBack_frame"/>
		<origin rpy="1.5708 -1.5708 -3.14159" xyz="0.0523 0 0.0304"/>
		<axis xyz="0 0 0"/>
	</joint> -->
  <link name="CameraTop_frame"/>
  <joint name="CameraTop_sensor_fixedjoint" type="fixed">
    <parent link="Head"/>
    <child link="CameraTop_frame"/>
    <origin rpy="0 0 0" xyz="0.08601 0 0.16284"/>
    <axis xyz="0 0 0"/>
  </joint>
  <link name="SurroundingLeftLaser_device_frame"/>
  <joint name="LaserSensor/Left_sensor_fixedjoint" type="fixed">
    <parent link="Tibia"/>
    <child link="SurroundingLeftLaser_device_frame"/>
    <origin rpy="0 0.349066 1.5708" xyz="-0.018 0.0899 -0.0759"/>
    <axis xyz="0 0 0"/>
  </joint>
  <link name="CameraDepth_frame"/>
  <joint name="CameraDepth_sensor_fixedjoint" type="fixed">
    <parent link="Head"/>
    <child link="CameraDepth_frame"/>
    <origin rpy="0 0 0" xyz="0.05138 0.039 0.1194"/>
    <axis xyz="0 0 0"/>
  </joint>
  <link name="SurroundingRightLaser_frame"/>
  <joint name="LaserSensor/Right_projected_sensor_fixedjoint" type="fixed">
    <parent link="Tibia"/>
    <child link="SurroundingRightLaser_frame"/>
    <origin rpy="0 0 -1.5707963267948966" xyz="-0.08600 -0.10100 -0.30000"/>
    <axis xyz="0 0 0"/>
  </joint>
  <link name="HeadTouchFront_frame"/>
  <joint name="Head/Touch/Front_sensor_fixedjoint" type="fixed">
    <parent link="Head"/>
    <child link="HeadTouchFront_frame"/>
    <origin rpy="0 0.20944 0" xyz="0.028175 0 0.21267"/>
    <axis xyz="0 0 0"/>
  </joint>
  <link name="VerticalRightLaser_frame"/>
  <joint name="LaserSensor/VerticalRight_sensor_fixedjoint" type="fixed">
    <parent link="Tibia"/>
    <child link="VerticalRightLaser_frame"/>
    <origin rpy="0 0.349066 0" xyz="0.0562 0 -0.0692"/>
    <axis xyz="0 0 0"/>
  </joint>
  <link name="SonarFront_frame"/>
  <joint name="Sonar/Front_sensor_fixedjoint" type="fixed">
    <parent link="Tibia"/>
    <child link="SonarFront_frame"/>
    <origin rpy="0 -0.322858 0" xyz="0.0699 0 -0.1023"/>
    <axis xyz="0 0 0"/>
  </joint>
  <link name="BumperFL_frame"/>
  <joint name="Bumper/FrontLeft_sensor_fixedjoint" type="fixed">
    <parent link="Tibia"/>
    <child link="BumperFL_frame"/>
    <origin rpy="0 0 0.48886" xyz="0.129 0.227 -0.264"/>
    <axis xyz="0 0 0"/>
  </joint>
  <link name="CameraBottom_frame"/>
  <joint name="CameraBottom_sensor_fixedjoint" type="fixed">
    <parent link="Head"/>
    <child link="CameraBottom_frame"/>
    <origin rpy="0 0.698132 0" xyz="0.09262 0 0.06177"/>
    <axis xyz="0 0 0"/>
  </joint>
  <link name="CameraTop_optical_frame"/>
  <joint name="CameraTop_optical_frame_fixedjoint" type="fixed">
    <parent link="CameraTop_frame"/>
    <child link="CameraTop_optical_frame"/>
    <origin rpy="-1.57079632679 0 -1.57079632679" xyz="0 0 0"/>
  </joint>
  <link name="ImuBaseAccelerometer_frame"/>
  <joint name="AccelerometerBase_sensor_fixedjoint" type="fixed">
    <parent link="Tibia"/>
    <child link="ImuBaseAccelerometer_frame"/>
    <origin rpy="0 0 0" xyz="0.0147 -0.0017 -0.26319"/>
    <axis xyz="0 0 0"/>
  </joint>
  <link name="ImuTorsoGyrometer_frame"/>
  <joint name="Gyrometer_sensor_fixedjoint" type="fixed">
    <parent link="torso"/>
    <child link="ImuTorsoGyrometer_frame"/>
    <origin rpy="0 0 0" xyz="0.00204 -0.03491 -0.00959"/>
    <axis xyz="0 0 0"/>
  </joint>
  <link name="Tablet_frame"/>
  <joint name="Tablet_sensor_fixedjoint" type="fixed">
    <parent link="torso"/>
    <child link="Tablet_frame"/>
    <origin rpy="0 -0.523599 0" xyz="0.0839249 0 0.06251"/>
    <axis xyz="0 0 0"/>
  </joint>
  <link name="HeadTouchRear_frame"/>
  <joint name="Head/Touch/Rear_sensor_fixedjoint" type="fixed">
    <parent link="Head"/>
    <child link="HeadTouchRear_frame"/>
    <origin rpy="0 -0.314159 0" xyz="-0.03376 0 0.21052"/>
    <axis xyz="0 0 0"/>
  </joint>
  <link name="BumperFR_frame"/>
  <joint name="Bumper/FrontRight_sensor_fixedjoint" type="fixed">
    <parent link="Tibia"/>
    <child link="BumperFR_frame"/>
    <origin rpy="0 0 -0.48886" xyz="0.129 -0.227 -0.264"/>
    <axis xyz="0 0 0"/>
  </joint>
  <link name="SurroundingFrontLaser_frame"/>
  <joint name="LaserSensor/Front_projected_sensor_fixedjoint" type="fixed">
    <parent link="Tibia"/>
    <child link="SurroundingFrontLaser_frame"/>
    <origin rpy="0 0 0" xyz="0.12960 -0.02700 -0.30010"/>
    <axis xyz="0 0 0"/>
  </joint>
  <link name="ChestButton_frame"/>
  <joint name="ChestBoard/Button_sensor_fixedjoint" type="fixed">
    <parent link="torso"/>
    <child link="ChestButton_frame"/>
    <origin rpy="0 0 0" xyz="0.049871 0.001588 0.055163"/>
    <axis xyz="0 0 0"/>
  </joint>
  <link name="HeadTouchMiddle_frame"/>
  <joint name="Head/Touch/Middle_sensor_fixedjoint" type="fixed">
    <parent link="Head"/>
    <child link="HeadTouchMiddle_frame"/>
    <origin rpy="0 -0.0349066 0" xyz="0.0041 0 0.2159"/>
    <axis xyz="0 0 0"/>
  </joint>
  <link name="SurroundingFrontLaser_fake_hokuyo_frame"/>
  <joint name="LaserSensor/Front_fake_hokuyo_projected_sensor_fixedjoint" type="fixed">
    <parent link="Tibia"/>
    <child link="SurroundingFrontLaser_fake_hokuyo_frame"/>
    <origin rpy="0 0 0" xyz="0.0562 0 -0.334"/>
    <axis xyz="0 0 0"/>
  </joint>
  <link name="WheelFL_link">
    <inertial>
      <mass value="1.58028"/>
      <inertia ixx="0.00299756" ixy="6.3068e-07" ixz="5.56903e-06" iyy="0.00303229" iyz="-9.0408e-07" izz="0.00296585"/>
      <origin rpy="0 0 0" xyz="0 0 0"/>
    </inertial>
    <visual>
      <geometry>
        <mesh filename="package://pepper_meshes/meshes/1.0/WheelFL.dae" scale="0.1 0.1 0.1"/>
      </geometry>
      <origin rpy="0 0 0" xyz="0 0 0"/>
    </visual>
    <!-- 		<collision>
			<geometry>
				<mesh filename="package://pepper_meshes/meshes/1.0/WheelFL_0.10.stl" scale="0.1 0.1 0.1"/>
			</geometry>
			<origin rpy="0 0 0" xyz="0 0 0"/>
		</collision> -->
  </link>
  <joint name="WheelFL" type="continuous">
    <parent link="Tibia"/>
    <child link="WheelFL_link"/>
    <origin rpy="0 0 1.07517" xyz="0.09 0.155 -0.264"/>
    <axis xyz="1.0 0 0"/>
    <limit effort="3.25" lower="0" upper="0" velocity="6.28319"/>
  </joint>
  <link name="WheelB_link">
    <inertial>
      <mass value="1.58028"/>
      <inertia ixx="0.00299756" ixy="6.3068e-07" ixz="5.56903e-06" iyy="0.00303229" iyz="-9.0408e-07" izz="0.00296585"/>
      <origin rpy="0 0 0" xyz="0 0 0"/>
    </inertial>
    <visual>
      <geometry>
        <mesh filename="package://pepper_meshes/meshes/1.0/WheelB.dae" scale="0.1 0.1 0.1"/>
      </geometry>
      <origin rpy="0 0 0" xyz="0 0 0"/>
    </visual>
    <!-- 		<collision>
			<geometry>
				<mesh filename="package://pepper_meshes/meshes/1.0/WheelB_0.10.stl" scale="0.1 0.1 0.1"/>
			</geometry>
			<origin rpy="0 0 0" xyz="0 0 0"/>
		</collision> -->
  </link>
  <joint name="WheelB" type="continuous">
    <parent link="Tibia"/>
    <child link="WheelB_link"/>
    <origin rpy="0 0 -3.14159" xyz="-0.17 0 -0.264"/>
    <axis xyz="1.0 0 0"/>
    <limit effort="3.25" lower="0" upper="0" velocity="6.28319"/>
  </joint>
  <link name="WheelFR_link">
    <inertial>
      <mass value="1.58028"/>
      <inertia ixx="0.00299756" ixy="6.3068e-07" ixz="5.56903e-06" iyy="0.00303229" iyz="-9.0408e-07" izz="0.00296585"/>
      <origin rpy="0 0 0" xyz="0 0 0"/>
    </inertial>
    <visual>
      <geometry>
        <mesh filename="package://pepper_meshes/meshes/1.0/WheelFR.dae" scale="0.1 0.1 0.1"/>
      </geometry>
      <origin rpy="0 0 0" xyz="0 0 0"/>
    </visual>
    <!-- 		<collision>
			<geometry>
				<mesh filename="package://pepper_meshes/meshes/1.0/WheelFR_0.10.stl" scale="0.1 0.1 0.1"/>
			</geometry>
			<origin rpy="0 0 0" xyz="0 0 0"/>
		</collision> -->
  </link>
  <joint name="WheelFR" type="continuous">
    <parent link="Tibia"/>
    <child link="WheelFR_link"/>
    <origin rpy="0 0 -1.07517" xyz="0.09 -0.155 -0.264"/>
    <axis xyz="1.0 0 0"/>
    <limit effort="3.25" lower="0" upper="0" velocity="6.28319"/>
  </joint>
  <!-- <xacro:macro name="DisabledLinks" params="side side_small">
        <plugin name="${side}Finger11_link" filename="libroboticsgroup_gazebo_disable_link_plugin.so">
            <link>${side}Finger11_link</link>
        </plugin>
        <plugin name="${side}Finger12_link" filename="libroboticsgroup_gazebo_disable_link_plugin.so">
            <link>${side}Finger12_link</link>
        </plugin>
        <plugin name="${side}Finger13_link" filename="libroboticsgroup_gazebo_disable_link_plugin.so">
            <link>${side}Finger13_link</link>
        </plugin>
        <plugin name="${side}Finger21_link" filename="libroboticsgroup_gazebo_disable_link_plugin.so">
            <link>${side}Finger21_link</link>
        </plugin>
        <plugin name="${side}Finger22_link" filename="libroboticsgroup_gazebo_disable_link_plugin.so">
            <link>${side}Finger22_link</link>
        </plugin>
        <plugin name="${side}Finger23_link" filename="libroboticsgroup_gazebo_disable_link_plugin.so">
            <link>${side}Finger23_link</link>
        </plugin>
        <plugin name="${side}Finger31_link" filename="libroboticsgroup_gazebo_disable_link_plugin.so">
            <link>${side}Finger31_link</link>
        </plugin>
        <plugin name="${side}Finger32_link" filename="libroboticsgroup_gazebo_disable_link_plugin.so">
            <link>${side}Finger32_link</link>
        </plugin>
        <plugin name="${side}Finger33_link" filename="libroboticsgroup_gazebo_disable_link_plugin.so">
            <link>${side}Finger33_link</link>
        </plugin>
        <plugin name="${side}Finger41_link" filename="libroboticsgroup_gazebo_disable_link_plugin.so">
            <link>${side}Finger41_link</link>
        </plugin>
        <plugin name="${side}Finger42_link" filename="libroboticsgroup_gazebo_disable_link_plugin.so">
            <link>${side}Finger42_link</link>
        </plugin>
        <plugin name="${side}Finger43_link" filename="libroboticsgroup_gazebo_disable_link_plugin.so">
            <link>${side}Finger43_link</link>
        </plugin>
        <plugin name="${side}Thumb1_link" filename="libroboticsgroup_gazebo_disable_link_plugin.so">
            <link>${side}Thumb1_link</link>
        </plugin>
        <plugin name="${side}Thumb2_link" filename="libroboticsgroup_gazebo_disable_link_plugin.so">
            <link>${side}Thumb2_link</link>
        </plugin> 
        <plugin name="${side_small}_gripper" filename="libroboticsgroup_gazebo_disable_link_plugin.so">
            <link>${side_small}_gripper</link>
        </plugin>
    </xacro:macro>  -->
  <!-- MACROS FOR MIMIC JOINTS -->
  <!-- Fingers -->
  <!--    <xacro:macro name="FingerMimics" params="side num">
        <plugin name="mimic_${side}Finger${num}1" filename="libroboticsgroup_gazebo_mimic_joint_plugin.so">
            <joint>${side}Hand</joint>
            <mimicJoint>${side}Finger${num}1</mimicJoint>
            <multiplier>-${PI/4}</multiplier>
            <offset>${PI/4}</offset>
        </plugin>
        <plugin name="mimic_${side}Finger${num}2" filename="libroboticsgroup_gazebo_mimic_joint_plugin.so">
            <joint>${side}Hand</joint>
            <mimicJoint>${side}Finger${num}2</mimicJoint>
            <multiplier>-${PI/4}</multiplier>
            <offset>${PI/4}</offset>
        </plugin>
        <plugin name="mimic_${side}Finger${num}3" filename="libroboticsgroup_gazebo_mimic_joint_plugin.so">
            <joint>${side}Hand</joint>
            <mimicJoint>${side}Finger${num}3</mimicJoint>
            <multiplier>-${PI/4}</multiplier>
            <offset>${PI/4}</offset>
        </plugin>
    </xacro:macro> 
    <xacro:macro name="ThumbMimics" params="side">
        <plugin name="${side}Thumb1" filename="libroboticsgroup_gazebo_mimic_joint_plugin.so">
            <joint>${side}Hand</joint>
            <mimicJoint>${side}Thumb1</mimicJoint>
            <multiplier>-${PI/4}</multiplier>
            <offset>${PI/4}</offset>
        </plugin>
        <plugin name="${side}Thumb2" filename="libroboticsgroup_gazebo_mimic_joint_plugin.so">
            <joint>${side}Hand</joint>
            <mimicJoint>${side}Thumb2</mimicJoint>
            <multiplier>-${PI/4}</multiplier>
            <offset>${PI/4}</offset>
        </plugin>
    </xacro:macro> -->
  <!-- GAZEBO ROS CONTROL -->
  <gazebo>
    <plugin filename="libgazebo_ros_control.so" name="gazebo_ros_control">
      <robotNamespace/>
      <legacyModeNS>true</legacyModeNS>
      <robotSimType>gazebo_ros_control/DefaultRobotHWSim</robotSimType>
    </plugin>
    <!--        <xacro:FingerMimics side="L" num="1"/>
        <xacro:FingerMimics side="L" num="2"/>
        <xacro:FingerMimics side="L" num="3"/>
        <xacro:FingerMimics side="L" num="4"/>
        <xacro:FingerMimics side="R" num="1"/>
        <xacro:FingerMimics side="R" num="2"/>
        <xacro:FingerMimics side="R" num="3"/>
        <xacro:FingerMimics side="R" num="4"/>

        <xacro:ThumbMimics side="L"/>
        <xacro:ThumbMimics side="R"/>

        <xacro:DisabledLinks side="L" side_small="l"/>
        <xacro:DisabledLinks side="R" side_small="r"/>  -->
  </gazebo>
  <!-- END OF GAZEBO ROS CONTROL PLUGIN -->
  <!-- GAZEBO MATERIALS -->
  <gazebo reference="base_footprint">
    <turnGravityOff>false</turnGravityOff>
  </gazebo>
  <gazebo reference="base_link">
    <turnGravityOff>false</turnGravityOff>
  </gazebo>
  <gazebo reference="torso">
    <mu1>0.5</mu1>
    <mu2>0.5</mu2>
    <selfCollide>false</selfCollide>
    <turnGravityOff>false</turnGravityOff>
  </gazebo>
  <gazebo reference="Neck">
    <mu1>0.5</mu1>
    <mu2>0.5</mu2>
    <selfCollide>false</selfCollide>
    <turnGravityOff>false</turnGravityOff>
  </gazebo>
  <gazebo reference="Head">
    <mu1>0.5</mu1>
    <mu2>0.5</mu2>
    <selfCollide>false</selfCollide>
    <turnGravityOff>false</turnGravityOff>
  </gazebo>
  <gazebo reference="gaze">
    <mu1>0.5</mu1>
    <mu2>0.5</mu2>
    <selfCollide>false</selfCollide>
    <turnGravityOff>false</turnGravityOff>
  </gazebo>
  <!-- ARMS -->
  <!--     <gazebo reference="LShoulder">
        <mu1>0.5</mu1>
        <mu2>0.5</mu2>
        <selfCollide>false</selfCollide>
        <turnGravityOff>false</turnGravityOff>
    </gazebo>
    <gazebo reference="LBicep">
        <mu1>0.5</mu1>
        <mu2>0.5</mu2>
        <selfCollide>false</selfCollide>
        <turnGravityOff>false</turnGravityOff>
    </gazebo>
    <gazebo reference="LElbow">
        <mu1>0.5</mu1>
        <mu2>0.5</mu2>
        <selfCollide>false</selfCollide>
        <turnGravityOff>false</turnGravityOff>
    </gazebo>
    <gazebo reference="LForeArm">
        <mu1>0.5</mu1>
        <mu2>0.5</mu2>
        <selfCollide>false</selfCollide>
        <turnGravityOff>false</turnGravityOff>
    </gazebo> 
    <gazebo reference="l_wrist">
        <mu1>0.5</mu1>
        <mu2>0.5</mu2>
        <selfCollide>false</selfCollide>
        <turnGravityOff>false</turnGravityOff>
    </gazebo>
    <gazebo reference="l_gripper">
        <mu1>0.5</mu1>
        <mu2>0.5</mu2>
        <selfCollide>false</selfCollide>
        <turnGravityOff>true</turnGravityOff>
    </gazebo>

    <gazebo reference="RShoulder">
        <mu1>0.5</mu1>
        <mu2>0.5</mu2>
        <selfCollide>false</selfCollide>
        <turnGravityOff>false</turnGravityOff>
    </gazebo>
    <gazebo reference="RBicep">
        <mu1>0.5</mu1>
        <mu2>0.5</mu2>
        <selfCollide>false</selfCollide>
        <turnGravityOff>false</turnGravityOff>
    </gazebo>
    <gazebo reference="RElbow">
        <mu1>0.5</mu1>
        <mu2>0.5</mu2>
        <selfCollide>false</selfCollide>
        <turnGravityOff>false</turnGravityOff>
    </gazebo>
    <gazebo reference="RForeArm">
        <mu1>0.5</mu1>
        <mu2>0.5</mu2>
        <selfCollide>false</selfCollide>
        <turnGravityOff>false</turnGravityOff>
    </gazebo> 
    <gazebo reference="r_wrist">
        <mu1>0.5</mu1>
        <mu2>0.5</mu2>
        <selfCollide>false</selfCollide>
        <turnGravityOff>false</turnGravityOff>
    </gazebo>
    <gazebo reference="r_gripper">
        <mu1>0.5</mu1>
        <mu2>0.5</mu2>
        <selfCollide>false</selfCollide>
        <turnGravityOff>true</turnGravityOff>
    </gazebo> -->
  <!--     <gazebo reference="LFinger11_link">
        <mu1>0.5</mu1>
        <mu2>0.5</mu2>
        <selfCollide>false</selfCollide>
        <turnGravityOff>true</turnGravityOff>
    </gazebo>
    <gazebo reference="LFinger12_link">
        <mu1>0.5</mu1>
        <mu2>0.5</mu2>
        <selfCollide>false</selfCollide>
        <turnGravityOff>true</turnGravityOff>
    </gazebo>
    <gazebo reference="LFinger13_link">
        <mu1>0.5</mu1>
        <mu2>0.5</mu2>
        <selfCollide>false</selfCollide>
        <turnGravityOff>true</turnGravityOff>
    </gazebo>
    <gazebo reference="LFinger21_link">
        <mu1>0.5</mu1>
        <mu2>0.5</mu2>
        <selfCollide>false</selfCollide>
        <turnGravityOff>true</turnGravityOff>
    </gazebo>
    <gazebo reference="LFinger22_link">
        <mu1>0.5</mu1>
        <mu2>0.5</mu2>
        <selfCollide>false</selfCollide>
        <turnGravityOff>true</turnGravityOff>
    </gazebo>
    <gazebo reference="LFinger23_link">
        <mu1>0.5</mu1>
        <mu2>0.5</mu2>
        <selfCollide>false</selfCollide>
        <turnGravityOff>true</turnGravityOff>
    </gazebo>

    <gazebo reference="LFinger31_link">
        <mu1>0.5</mu1>
        <mu2>0.5</mu2>
        <selfCollide>false</selfCollide>
        <turnGravityOff>true</turnGravityOff>
    </gazebo>
    <gazebo reference="LFinger32_link">
        <mu1>0.5</mu1>
        <mu2>0.5</mu2>
        <selfCollide>false</selfCollide>
        <turnGravityOff>true</turnGravityOff>
    </gazebo>
    <gazebo reference="LFinger33_link">
        <mu1>0.5</mu1>
        <mu2>0.5</mu2>
        <selfCollide>false</selfCollide>
        <turnGravityOff>true</turnGravityOff>
    </gazebo>
    <gazebo reference="LFinger41_link">
        <mu1>0.5</mu1>
        <mu2>0.5</mu2>
        <selfCollide>false</selfCollide>
        <turnGravityOff>true</turnGravityOff>
    </gazebo>
    <gazebo reference="LFinger42_link">
        <mu1>0.5</mu1>
        <mu2>0.5</mu2>
        <selfCollide>false</selfCollide>
        <turnGravityOff>true</turnGravityOff>
    </gazebo>
    <gazebo reference="LFinger43_link">
        <mu1>0.5</mu1>
        <mu2>0.5</mu2>
        <selfCollide>false</selfCollide>
        <turnGravityOff>true</turnGravityOff>
    </gazebo>

    <gazebo reference="LThumb1_link">
        <mu1>0.5</mu1>
        <mu2>0.5</mu2>
        <selfCollide>false</selfCollide>
        <turnGravityOff>true</turnGravityOff>
    </gazebo>
    <gazebo reference="LThumb2_link">
        <mu1>0.5</mu1>
        <mu2>0.5</mu2>
        <selfCollide>false</selfCollide>
        <turnGravityOff>true</turnGravityOff>
    </gazebo>  -->
  <gazebo reference="Hip">
    <mu1>0.5</mu1>
    <mu2>0.5</mu2>
    <selfCollide>false</selfCollide>
    <turnGravityOff>false</turnGravityOff>
  </gazebo>
  <gazebo reference="Pelvis">
    <mu1>0.5</mu1>
    <mu2>0.5</mu2>
    <selfCollide>false</selfCollide>
    <turnGravityOff>false</turnGravityOff>
  </gazebo>
  <gazebo reference="Tibia">
    <mu1>0.0</mu1>
    <mu2>0.0</mu2>
    <kp value="10000000.0"/>
    <kd value="1.0"/>
    <fdir1 value="1 0 0"/>
    <selfCollide>false</selfCollide>
    <turnGravityOff>false</turnGravityOff>
  </gazebo>
  <gazebo reference="WheelFL_link">
    <mu1>1</mu1>
    <mu2>0</mu2>
    <kp value="10000000.0"/>
    <kd value="1.0"/>
    <fdir1 value="1 0 0"/>
    <minDepth>0.003</minDepth>
    <turnGravityOff>false</turnGravityOff>
  </gazebo>
  <gazebo reference="WheelB_link">
    <mu1>0.5</mu1>
    <mu2>0.5</mu2>
    <kp value="10000000.0"/>
    <kd value="1.0"/>
    <fdir1 value="1 0 0"/>
    <minDepth>0.003</minDepth>
    <turnGravityOff>false</turnGravityOff>
  </gazebo>
  <gazebo reference="WheelFR_link">
    <mu1>0</mu1>
    <mu2>1</mu2>
    <kp value="10000000.0"/>
    <kd value="1.0"/>
    <fdir1 value="0 1 0"/>
    <minDepth>0.003</minDepth>
    <turnGravityOff>false</turnGravityOff>
  </gazebo>
  <!--   <gazebo reference="RFinger11_link">
        <mu1>0.5</mu1>
        <mu2>0.5</mu2>
        <selfCollide>false</selfCollide>
        <turnGravityOff>true</turnGravityOff>
    </gazebo>
    <gazebo reference="RFinger12_link">
        <mu1>0.5</mu1>
        <mu2>0.5</mu2>
        <selfCollide>false</selfCollide>
        <turnGravityOff>true</turnGravityOff>
    </gazebo>
    <gazebo reference="RFinger13_link">
        <mu1>0.5</mu1>
        <mu2>0.5</mu2>
        <selfCollide>false</selfCollide>
        <turnGravityOff>true</turnGravityOff>
    </gazebo>
    <gazebo reference="RFinger21_link">
        <mu1>0.5</mu1>
        <mu2>0.5</mu2>
        <selfCollide>false</selfCollide>
        <turnGravityOff>true</turnGravityOff>
    </gazebo>
    <gazebo reference="RFinger22_link">
        <mu1>0.5</mu1>
        <mu2>0.5</mu2>
        <selfCollide>false</selfCollide>
        <turnGravityOff>true</turnGravityOff>
    </gazebo>
    <gazebo reference="RFinger23_link">
        <mu1>0.5</mu1>
        <mu2>0.5</mu2>
        <selfCollide>false</selfCollide>
        <turnGravityOff>true</turnGravityOff>
    </gazebo>
    <gazebo reference="RFinger31_link">
        <mu1>0.5</mu1>
        <mu2>0.5</mu2>
        <selfCollide>false</selfCollide>
        <turnGravityOff>true</turnGravityOff>
    </gazebo>
    <gazebo reference="RFinger32_link">
        <mu1>0.5</mu1>
        <mu2>0.5</mu2>
        <selfCollide>false</selfCollide>
        <turnGravityOff>true</turnGravityOff>
    </gazebo>
    <gazebo reference="RFinger33_link">
        <mu1>0.5</mu1>
        <mu2>0.5</mu2>
        <selfCollide>false</selfCollide>
        <turnGravityOff>true</turnGravityOff>
    </gazebo>
    <gazebo reference="RFinger41_link">
        <mu1>0.5</mu1>
        <mu2>0.5</mu2>
        <selfCollide>false</selfCollide>
        <turnGravityOff>true</turnGravityOff>
    </gazebo>
    <gazebo reference="RFinger42_link">
        <mu1>0.5</mu1>
        <mu2>0.5</mu2>
        <selfCollide>false</selfCollide>
        <turnGravityOff>true</turnGravityOff>
    </gazebo>
    <gazebo reference="RFinger43_link">
        <mu1>0.5</mu1>
        <mu2>0.5</mu2>
        <selfCollide>false</selfCollide>
        <turnGravityOff>true</turnGravityOff>
    </gazebo>

    <gazebo reference="RThumb1_link">
        <mu1>0.5</mu1>
        <mu2>0.5</mu2>
        <selfCollide>false</selfCollide>
        <turnGravityOff>true</turnGravityOff>
    </gazebo>
    <gazebo reference="RThumb2_link">
        <mu1>0.5</mu1>
        <mu2>0.5</mu2>
        <selfCollide>false</selfCollide>
        <turnGravityOff>true</turnGravityOff>
    </gazebo> -->
  <!--
        RGB CAMERAS:
-->
  <gazebo reference="CameraTop_frame">
    <sensor name="CameraTop" type="camera">
      <update_rate>5.0</update_rate>
      <camera name="camera_top">
        <horizontal_fov>1.0</horizontal_fov>
        <image>
          <width>640</width>
          <height>480</height>
          <format>R8G8B8</format>
        </image>
        <clip>
          <near>0.3</near>
          <far>500</far>
        </clip>
        <noise>
          <type>gaussian</type>
          <mean>0.0</mean>
          <stddev>0.007</stddev>
        </noise>
      </camera>
      <plugin filename="libgazebo_ros_camera.so" name="camera_controller">
        <!-- <robotNamespace>/pepper</robotNamespace> -->
        <alwaysOn>true</alwaysOn>
        <updateRate>5.0</updateRate>
        <cameraName>/pepper/camera/front</cameraName>
        <imageTopicName>image_raw</imageTopicName>
        <cameraInfoTopicName>camera_info</cameraInfoTopicName>
        <frameName>CameraTop_optical_frame</frameName>
        <hackBaseline>0.07</hackBaseline>
        <distortionK1>-0.0545211</distortionK1>
        <distortionK2>0.06919734</distortionK2>
        <distortionK3>-0.0241095</distortionK3>
        <distortionT1>-0.0112245</distortionT1>
        <distortionT2>0.0</distortionT2>
      </plugin>
    </sensor>
  </gazebo>
  <gazebo reference="CameraBottom_frame">
    <sensor name="CameraBottom" type="camera">
      <update_rate>5.0</update_rate>
      <camera name="camera_bottom">
        <horizontal_fov>1.0</horizontal_fov>
        <image>
          <width>640</width>
          <height>480</height>
          <format>R8G8B8</format>
        </image>
        <clip>
          <near>0.05</near>
          <far>500</far>
        </clip>
        <noise>
          <type>gaussian</type>
          <mean>0.0</mean>
          <stddev>0.007</stddev>
        </noise>
      </camera>
      <plugin filename="libgazebo_ros_camera.so" name="camera_controller">
        <!-- <robotNamespace>/pepper</robotNamespace> -->
        <alwaysOn>true</alwaysOn>
        <updateRate>5.0</updateRate>
        <cameraName>/pepper/camera/bottom</cameraName>
        <imageTopicName>image_raw</imageTopicName>
        <cameraInfoTopicName>camera_info</cameraInfoTopicName>
        <frameName>CameraBottom_optical_frame</frameName>
        <hackBaseline>0.07</hackBaseline>
        <distortionK1>-0.0648764</distortionK1>
        <distortionK2>0.06125202</distortionK2>
        <distortionK3>0.00382815</distortionK3>
        <distortionT1>-0.00551104</distortionT1>
        <distortionT2>0.0</distortionT2>
      </plugin>
    </sensor>
  </gazebo>
  <gazebo reference="CameraDepth_frame">
    <sensor name="CameraDepth_frame_sensor" type="depth">
      <always_on>true</always_on>
      <update_rate>30.0</update_rate>
      <camera>
        <horizontal_fov>1.0122909661567778</horizontal_fov>
        <image>
          <format>B8G8R8</format>
          <width>320</width>
          <height>240</height>
        </image>
        <clip>
          <near>0.4</near>
          <far>8.0</far>
        </clip>
      </camera>
      <!-- TODO: Fork our own https://github.com/ros-simulation/gazebo_ros_pkgs/blob/kinetic-devel/gazebo_plugins/src/gazebo_ros_openni_kinect.cpp#L396
        to have the depth image be the same format -->
      <plugin filename="libgazebo_ros_camera.so" name="CameraDepth_frame_controller">
        <alwaysOn>true</alwaysOn>
        <updateRate>30.0</updateRate>
        <cameraName>pepper/camera</cameraName>
        <imageTopicName>ir/image_raw</imageTopicName>
        <cameraInfoTopicName>depth/camera_info</cameraInfoTopicName>
        <depthImageTopicName>depth/image_raw</depthImageTopicName>
        <pointCloudTopicName>depth/points</pointCloudTopicName>
        <frameName>CameraDepth_optical_frame</frameName>
        <pointCloudCutoff>0.4</pointCloudCutoff>
        <pointCloudCutoffMax>8.0</pointCloudCutoffMax>
        <useDepth16UC1Format>true</useDepth16UC1Format>
        <distortionK1>0.0015006388343578579</distortionK1>
        <distortionK2>-0.0391088434247705</distortionK2>
        <distortionK3>0.0</distortionK3>
        <distortionT1>0.002366597891470404</distortionT1>
        <distortionT2>0.004792417377891919</distortionT2>
        <CxPrime>0.0</CxPrime>
        <Cx>166.86986665284704</Cx>
        <Cy>126.63268197434216</Cy>
        <focalLength>288.647970</focalLength>
        <hackBaseline>0.0</hackBaseline>
        <!-- <distortionK1>0.00000001</distortionK1>
          <distortionK2>0.00000001</distortionK2>
          <distortionK3>0.00000001</distortionK3>
          <distortionT1>0.00000001</distortionT1>
          <distortionT2>0.00000001</distortionT2> -->
      </plugin>
    </sensor>
  </gazebo>
  <!-- 
    BUMPERS

<gazebo reference="BumperB_frame">
  <mu1>0.5</mu1>
  <mu2>0.5</mu2>
  <selfCollide>false</selfCollide>
  <turnGravityOff>false</turnGravityOff>
  <fdir1>1 0 0</fdir1>
  <maxVel>0.1</maxVel>
  <minDepth>0.003</minDepth>
  <sensor name="BumperB" type="contact">
    <always_on>1</always_on>
    <update_rate>20</update_rate>
    <visualize>false</visualize>
    <contact>
      <collision>BumperB_frame_collision</collision>
    </contact>
    <plugin filename="libgazebo_ros_bumper.so" name="gazebo_pepper_BumperB">
      <robotNamespace>/pepper</robotNamespace>
      <alwaysOn>true</alwaysOn>
      <bumperTopicName>Bumper/Back</bumperTopicName>
      <frameName>BumperB_frame</frameName>
    </plugin>
  </sensor>
</gazebo>

<gazebo reference="BumperFL_frame">
  <mu1>0.5</mu1>
  <mu2>0.5</mu2>
  <selfCollide>false</selfCollide>
  <turnGravityOff>false</turnGravityOff>
  <fdir1>1 0 0</fdir1>
  <maxVel>0.1</maxVel>
  <minDepth>0.003</minDepth>
  <sensor name="BumperFL" type="contact">
    <always_on>1</always_on>
    <update_rate>20</update_rate>
    <visualize>false</visualize>
    <contact>
      <collision>BumperFL_frame_collision</collision>
    </contact>
    <plugin filename="libgazebo_ros_bumper.so" name="gazebo_pepper_BumperFL">
      <robotNamespace>/pepper</robotNamespace>
      <alwaysOn>true</alwaysOn>
      <bumperTopicName>Bumper/FrontLeft</bumperTopicName>
      <frameName>BumperFL_frame</frameName>
    </plugin>
  </sensor>
</gazebo>

<gazebo reference="BumperFR_frame">
  <mu1>0.5</mu1>
  <mu2>0.5</mu2>
  <selfCollide>false</selfCollide>
  <turnGravityOff>false</turnGravityOff>
  <fdir1>1 0 0</fdir1>
  <maxVel>0.1</maxVel>
  <minDepth>0.003</minDepth>
  <sensor name="BumperFR" type="contact">
    <always_on>1</always_on>
    <update_rate>20</update_rate>
    <visualize>false</visualize>
    <contact>
      <collision>BumperFR_frame_collision</collision>
    </contact>
    <plugin filename="libgazebo_ros_bumper.so" name="gazebo_pepper_BumperFR">
      <robotNamespace>/pepper</robotNamespace>
      <alwaysOn>true</alwaysOn>
      <bumperTopicName>Bumper/FrontRight</bumperTopicName>
      <frameName>BumperFR_frame</frameName>
    </plugin>
  </sensor>
</gazebo>
-->
  <!--
    Sonars
-->
  <gazebo reference="SonarBack_frame">
    <sensor name="SonarBack" type="ray">
      <pose>0 0 0 0 0 0</pose>
      <update_rate>20</update_rate>
      <visualize>false</visualize>
      <ray>
        <scan>
          <horizontal>
            <samples>5</samples>
            <resolution>3</resolution>
            <min_angle>-0.52</min_angle>
            <max_angle>0.52</max_angle>
          </horizontal>
          <vertical>
            <samples>5</samples>
            <resolution>3</resolution>
            <min_angle>-0.52</min_angle>
            <max_angle>0.52</max_angle>
          </vertical>
        </scan>
        <range>
          <min>0.0</min>
          <max>5.0</max>
          <resolution>3</resolution>
        </range>
      </ray>
      <plugin filename="libgazebo_ros_range.so" name="gazebo_ros_range">
        <robotNamespace>/pepper</robotNamespace>
        <gaussianNoise>0.05</gaussianNoise>
        <alwaysOn>true</alwaysOn>
        <updateRate>20</updateRate>
        <topicName>sonar_back</topicName>
        <frameName>SonarBack_frame</frameName>
        <minRange>0.0</minRange>
        <maxRange>5.0</maxRange>
        <fov>1.05</fov>
        <radiation>ultrasound</radiation>
      </plugin>
    </sensor>
  </gazebo>
  <gazebo reference="SonarFront_frame">
    <sensor name="SonarFront" type="ray">
      <pose>0 0 0 0 0 0</pose>
      <update_rate>20</update_rate>
      <visualize>false</visualize>
      <ray>
        <scan>
          <horizontal>
            <samples>5</samples>
            <resolution>3</resolution>
            <min_angle>-0.52</min_angle>
            <max_angle>0.52</max_angle>
          </horizontal>
          <vertical>
            <samples>5</samples>
            <resolution>3</resolution>
            <min_angle>-0.52</min_angle>
            <max_angle>0.52</max_angle>
          </vertical>
        </scan>
        <range>
          <min>0.0</min>
          <max>5.0</max>
          <resolution>3</resolution>
        </range>
      </ray>
      <plugin filename="libgazebo_ros_range.so" name="gazebo_ros_range">
        <robotNamespace>/pepper</robotNamespace>
        <gaussianNoise>0.05</gaussianNoise>
        <alwaysOn>true</alwaysOn>
        <updateRate>20</updateRate>
        <topicName>sonar_front</topicName>
        <frameName>SonarFront_frame</frameName>
        <minRange>0.0</minRange>
        <maxRange>5.0</maxRange>
        <fov>1.05</fov>
        <radiation>ultrasound</radiation>
      </plugin>
    </sensor>
  </gazebo>
  <!-- Drive controller -->
  <gazebo>
    <plugin filename="libgazebo_ros_model_velocity.so" name="base_drive_controller">
      <robotNamespace>/pepper</robotNamespace>
      <commandTopic>cmd_vel</commandTopic>
      <outputVelocityTopic>output_vel</outputVelocityTopic>
      <updateRate>50.0</updateRate>
      <commandTimeout>0.5</commandTimeout>
      <!-- Publish odometry as needed -->
      <odometryTopic>odom</odometryTopic>
      <odometryFrame>odom</odometryFrame>
      <odometryRate>20.0</odometryRate>
      <publishOdometryTf>true</publishOdometryTf>
      <robotBaseFrame>base_footprint</robotBaseFrame>
      <!-- As measured in real robot odom_alpha3 and odom_alpha1 -->
      <gaussianNoiseXY>0.02</gaussianNoiseXY>
      <gaussianNoiseYaw>0.02645</gaussianNoiseYaw>
      <!-- To simulate closer to the real robot we modified the
      theoretical limits -->
      <linearVelocityLimit>0.55</linearVelocityLimit>
      <angularVelocityLimit>2.0</angularVelocityLimit>
      <linearAccelerationLimit>0.44000000000000006</linearAccelerationLimit>
      <angularAccelerationLimit>2.4000000000000004</angularAccelerationLimit>
      <linearJerkLimit>4.5</linearJerkLimit>
      <angularJerkLimit>45.0</angularJerkLimit>
    </plugin>
  </gazebo>
  <gazebo>
    <plugin filename="libgazebo_ros_p3d.so" name="ground_truth">
      <frameName>world</frameName>
      <bodyName>base_footprint</bodyName>
      <topicName>/pepper/odom_groundtruth</topicName>
      <updateRate>20.0</updateRate>
    </plugin>
  </gazebo>
  <!-- Front -->
  <gazebo reference="SurroundingFrontLaser_frame">
    <sensor name="front_laser_sensor" type="ray">
      <pose>0 0 0 0 0 0</pose>
      <visualize>true</visualize>
      <update_rate>6.25</update_rate>
      <ray>
        <scan>
          <horizontal>
            <samples>15</samples>
            <resolution>1</resolution>
            <min_angle>-0.5235987755982988</min_angle>
            <max_angle>0.5235987755982988</max_angle>
          </horizontal>
        </scan>
        <range>
          <min>0.3</min>
          <max>7.0</max>
          <resolution>0.005</resolution>
        </range>
        <noise>
          <type>gaussian</type>
          <mean>0.01</mean>
          <stddev>0.01</stddev>
        </noise>
      </ray>
      <plugin filename="libgazebo_ros_ray_sensor.so" name="gazebo_ros_front_laser_controller">
        <ros>
          <!-- <namespace>/laser/front</namespace> -->
          <remapping>~/out:=/laser/front/scan</remapping>
        </ros>
        <output_type>sensor_msgs/LaserScan</output_type>
        <!-- <topicName>/pepper/scan_front</topicName> -->
        <!-- <frameName>SurroundingFrontLaser_frame</frameName> -->
        <frame_name>SurroundingFrontLaser_frame</frame_name>
      </plugin>
    </sensor>
  </gazebo>
  <!-- Left -->
  <gazebo reference="SurroundingLeftLaser_frame">
    <sensor name="left_laser_sensor" type="ray">
      <pose>0 0 0 0 0 0</pose>
      <visualize>true</visualize>
      <update_rate>6.25</update_rate>
      <ray>
        <scan>
          <horizontal>
            <samples>15</samples>
            <resolution>1</resolution>
            <min_angle>-0.5235987755982988</min_angle>
            <max_angle>0.5235987755982988</max_angle>
          </horizontal>
        </scan>
        <range>
          <min>0.3</min>
          <max>7.0</max>
          <resolution>0.005</resolution>
        </range>
        <noise>
          <type>gaussian</type>
          <mean>0.01</mean>
          <stddev>0.01</stddev>
        </noise>
      </ray>
      <plugin filename="libgazebo_ros_ray_sensor.so" name="gazebo_ros_left_laser_controller">
        <ros>
          <!-- <namespace>/laser/front</namespace> -->
          <remapping>~/out:=/laser/left/scan</remapping>
        </ros>
        <output_type>sensor_msgs/LaserScan</output_type>
        <!-- <topicName>/pepper/scan_front</topicName> -->
        <!-- <frameName>SurroundingFrontLaser_frame</frameName> -->
        <frame_name>SurroundingLeftLaser_frame</frame_name>
        <!-- <topicName>/pepper/scan_left</topicName> -->
        <!-- <frameName>SurroundingLeftLaser_frame</frameName> -->
      </plugin>
    </sensor>
  </gazebo>
  <!-- Right -->
  <gazebo reference="SurroundingRightLaser_frame">
    <sensor name="right_laser_sensor" type="ray">
      <pose>0 0 0 0 0 0</pose>
      <visualize>true</visualize>
      <update_rate>6.25</update_rate>
      <ray>
        <scan>
          <horizontal>
            <samples>15</samples>
            <resolution>1</resolution>
            <min_angle>-0.5235987755982988</min_angle>
            <max_angle>0.5235987755982988</max_angle>
          </horizontal>
        </scan>
        <range>
          <min>0.3</min>
          <max>7.0</max>
          <resolution>0.005</resolution>
        </range>
        <noise>
          <type>gaussian</type>
          <mean>0.01</mean>
          <stddev>0.01</stddev>
        </noise>
      </ray>
      <plugin filename="libgazebo_ros_ray_sensor.so" name="gazebo_ros_right_laser_controller">
        <ros>
          <!-- <namespace>/laser/front</namespace> -->
          <remapping>~/out:=/laser/right/scan</remapping>
        </ros>
        <output_type>sensor_msgs/LaserScan</output_type>
        <frame_name>SurroundingRightLaser_frame</frame_name>
        <!-- <topicName>/pepper/scan_right</topicName> -->
        <!-- <frameName>SurroundingRightLaser_frame</frameName> -->
      </plugin>
    </sensor>
  </gazebo>
  <!-- Front -->
  <!-- <gazebo reference="SurroundingFrontLaser_fake_hokuyo_frame">
    <sensor type="ray" name="fake_hokuyo_laser_sensor">
      <pose>0 0 0 0 0 0</pose>
      <visualize>false</visualize>
      <update_rate>6.25</update_rate>
      <ray>
        <scan>
          <horizontal>
            <samples>720</samples>
            <resolution>1</resolution>
            <min_angle>-1.570796</min_angle>
            <max_angle>1.570796</max_angle>
          </horizontal>
        </scan>
        <range>
          <min>0.1</min>
          <max>30.0</max>
          <resolution>0.01</resolution>
        </range>
        <noise>
          <type>gaussian</type>
          <mean>0.0</mean>
          <stddev>0.01</stddev>
        </noise>
      </ray>
      <plugin name="gazebo_ros_fake_hokuyo_laser_controller" filename="libgazebo_ros_laser.so">
        <topicName>/pepper/hokuyo_scan</topicName>
        <frameName>SurroundingFrontLaser_fake_hokuyo_frame</frameName>
      </plugin>
    </sensor>
  </gazebo> -->
  <!-- HEAD -->
  <transmission name="HeadYaw_Transmission">
    <type>transmission_interface/SimpleTransmission</type>
    <joint name="HeadYaw">
      <hardwareInterface>hardware_interface/VelocityJointInterface</hardwareInterface>
    </joint>
    <actuator name="HeadYaw_Motor">
      <mechanicalReduction>101.3</mechanicalReduction>
    </actuator>
  </transmission>
  <transmission name="HeadPitch_Transmission">
    <type>transmission_interface/SimpleTransmission</type>
    <joint name="HeadPitch">
      <hardwareInterface>hardware_interface/VelocityJointInterface</hardwareInterface>
    </joint>
    <actuator name="HeadPitch_Motor">
      <mechanicalReduction>118.1</mechanicalReduction>
    </actuator>
  </transmission>
  <!-- <xacro:arm_joints_transmissions side="L"/>
	<xacro:arm_joints_transmissions side="R"/> -->
  <!-- LEGS -->
  <transmission name="HipRoll_Transmission">
    <type>transmission_interface/SimpleTransmission</type>
    <joint name="HipRoll">
      <hardwareInterface>hardware_interface/VelocityJointInterface</hardwareInterface>
    </joint>
    <actuator name="HipRoll_Motor">
      <mechanicalReduction>108.33</mechanicalReduction>
    </actuator>
  </transmission>
  <transmission name="HipPitch_Transmission">
    <type>transmission_interface/SimpleTransmission</type>
    <joint name="HipPitch">
      <hardwareInterface>hardware_interface/VelocityJointInterface</hardwareInterface>
    </joint>
    <actuator name="HipPitch_Motor">
      <mechanicalReduction>108.33</mechanicalReduction>
    </actuator>
  </transmission>
  <transmission name="KneePitch_Transmission">
    <type>transmission_interface/SimpleTransmission</type>
    <joint name="KneePitch">
      <hardwareInterface>hardware_interface/VelocityJointInterface</hardwareInterface>
    </joint>
    <actuator name="KneePitch_Motor">
      <mechanicalReduction>108.33</mechanicalReduction>
    </actuator>
  </transmission>
  <!-- XACRO -->
  <!-- Disabling wheels, given they are not used in simulation anymore -->
  <!--         <xacro:macro name="wheel_joints_transmissions" params="side">
                <transmission name="Wheel${side}_Transmission">
                        <type>transmission_interface/SimpleTransmission</type>
                        <joint name="Wheel${side}">
                                <hardwareInterface>EffortJointInterface</hardwareInterface>
                        </joint>
                        <actuator name="Wheel${side}_Motor">
                                <mechanicalReduction>${speed_red_type5B}</mechanicalReduction>
                        </actuator>
                </transmission>
        </xacro:macro>
        <xacro:wheel_joints_transmissions side="FL"/>
        <xacro:wheel_joints_transmissions side="B"/>
        <xacro:wheel_joints_transmissions side="FR"/> -->
</robot>
